Workbook

Sheet Sheet1
A1: Date | B1: 阿根廷Merval指数 | C1: 巴西IBOVESPA指数 | D1: 澳大利亚S&P/ASX200指数 | E1: 美国道琼斯指数 | F1: 加拿大TSX指数 | G1: 美国罗素2000指数 | H1: 美国标普500指数 | I1: 美国纳斯达克工业指数 | J1: 墨西哥BMV指数 | K1: 智利SPCLXIGPA指数 | L1: 波兰华沙WIG20指数 | M1: 德国DAX30指数 | N1: 俄罗斯IRS指数 | O1: 法国CAC40指数 | P1: 荷兰AEX指数 | Q1: 瑞士SWI20指数 | R1: 土耳其XU100指数 | S1: 西班牙IBEX35指数 | T1: 英国富时100指数 | U1: 欧洲STOXX指数 | V1: 韩国KOSPI指数 | W1: 日经225指数 | X1: 以色列TA35指数 | Y1: 上证指数 | Z1: 深证成指 | AA1: 台湾加权指数 | AB1: 香港恒生指数 | AC1: 新加坡海峡时报指数 | AD1: 印度NIFTY指数 | AE1: 越南VN30指数 | AF1: 南非40指数 | AG1: 埃及EGX30指数 | AH1: 摩洛哥MASI指数 | AI1: 尼日利亚NSE30指数 | AJ1: 坦桑尼亚全股指数
A2: 40167 | B2: 2249.35 | C2: 67589 | D2: 4790.9 | E2: 10520.1 | F2: 11754.61 | G2: 634.07 | H2: 1126.48 | I2: 2285.69 | J2: 32548.53 | K2: 16420.43 | L2: 2371.07 | M2: 5957.44 | N2: =VLOOKUP(A2,'[1]俄罗斯交易系统市值加权指数历史数据 (1)'!$A:$B,2,) -> 1450.25 | O2: 3912.73 | P2: 333.6 | Q2: 6579.98 | R2: 516.61 | S2: 11967.5 | T2: 5402.41 | U2: 2957.03 | V2: =VLOOKUP(A2,[2]韩国KOSPI指数历史数据!$A:$B,2,) -> 1682.34 | W2: =VLOOKUP(A2,[3]日经225指数历史数据!$A:$B,2,) -> 10494.71 | X2: 1146.28 | Y2: =VLOOKUP(A2,[4]上证指数历史数据!$A:$B,2,) -> 3141.35 | Z2: =VLOOKUP(A2,[5]深证成份指数历史数据!$A:$B,2,) -> 13289.94 | AA2: =VLOOKUP(A2,[6]台湾加权指数历史数据!$A:$B,2,) -> 7972.59 | AB2: 21517 | AC2: 2837.7 | AD2: 5178.4 | AE2: =VLOOKUP(A2,[7]越南VN30指数历史数据!$A:$B,2,) -> 527.54 | AF2: 24969.9 | AG2: 9465.01 | AH2: 10426.73 | AI2: 829.26 | AJ2: 1192.07
A3: 40174 | B3: 2320.73 | C3: 68588 | D3: 4870.6 | E3: 10428.05 | F3: 11746.11 | G3: 625.39 | H3: 1115.1 | I3: 2269.15 | J3: 32120.47 | K3: 16630.91 | L3: 2388.72 | M3: 5957.43 | N3: =VLOOKUP(A3,'[1]俄罗斯交易系统市值加权指数历史数据 (1)'!$A:$B,2,) -> 1444.61 | O3: 3936.33 | P3: 335.33 | Q3: 6545.91 | R3: 528.25 | S3: 11940 | T3: 5412.88 | U3: 2964.96 | V3: =VLOOKUP(A3,[2]韩国KOSPI指数历史数据!$A:$B,2,) -> 1682.77 | W3: =VLOOKUP(A3,[3]日经225指数历史数据!$A:$B,2,) -> 10546.44 | X3: 1145.06 | Y3: =VLOOKUP(A3,[4]上证指数历史数据!$A:$B,2,) -> 3277.14 | Z3: =VLOOKUP(A3,[5]深证成份指数历史数据!$A:$B,2,) -> 13699.97 | AA3: =VLOOKUP(A3,[6]台湾加权指数历史数据!$A:$B,2,) -> 8188.11 | AB3: 21872.5 | AC3: 2897.62 | AD3: 5201.05 | AE3: =VLOOKUP(A3,[7]越南VN30指数历史数据!$A:$B,2,) -> 525.97 | AF3: 24996.97 | AG3: 9230.95 | AH3: 10443.81 | AI3: 848.08 | AJ3: 1192.37
A4: 40181 | B4: 2352.76 | C4: 70263 | D4: 4912.1 | E4: 10618.19 | F4: 11953.83 | G4: 644.56 | H4: 1144.98 | I4: 2317.17 | J4: 32892.04 | K4: 17193.74 | L4: 2440.42 | M4: 6037.61 | N4: =VLOOKUP(A4,'[1]俄罗斯交易系统市值加权指数历史数据 (1)'!$A:$B,2,) -> #N/A | O4: 4045.14 | P4: 341.94 | Q4: 6617.88 | R4: 547.98 | S4: 12163 | T4: 5534.24 | U4: 3017.85 | V4: =VLOOKUP(A4,[2]韩国KOSPI指数历史数据!$A:$B,2,) -> 1695.26 | W4: =VLOOKUP(A4,[3]日经225指数历史数据!$A:$B,2,) -> 10798.32 | X4: 1166.23 | Y4: =VLOOKUP(A4,[4]上证指数历史数据!$A:$B,2,) -> 3196 | Z4: =VLOOKUP(A4,[5]深证成份指数历史数据!$A:$B,2,) -> 13267.44 | AA4: =VLOOKUP(A4,[6]台湾加权指数历史数据!$A:$B,2,) -> 8280.9 | AB4: 22296.75 | AC4: 2922.76 | AD4: 5244.75 | AE4: =VLOOKUP(A4,[7]越南VN30指数历史数据!$A:$B,2,) -> 547.5 | AF4: 25586.73 | AG4: 9603.19 | AH4: 10782.2 | AI4: 889.55 | AJ4: 1190.97
A5: 40188 | B5: 2371.11 | C5: 68978 | D5: 4899.6 | E5: 10609.65 | F5: 11685.37 | G5: 637.96 | H5: 1136.03 | I5: 2287.99 | J5: 32262.3 | K5: 17347.91 | L5: 2442.38 | M5: 5875.97 | N5: =VLOOKUP(A5,'[1]俄罗斯交易系统市值加权指数历史数据 (1)'!$A:$B,2,) -> 1559.25 | O5: 3954.38 | P5: 337.99 | Q5: 6576.02 | R5: 540.06 | S5: 11845 | T5: 5455.37 | U5: 2940.25 | V5: =VLOOKUP(A5,[2]韩国KOSPI指数历史数据!$A:$B,2,) -> 1701.8 | W5: =VLOOKUP(A5,[3]日经225指数历史数据!$A:$B,2,) -> 10982.1 | X5: 1146.95 | Y5: =VLOOKUP(A5,[4]上证指数历史数据!$A:$B,2,) -> 3224.15 | Z5: =VLOOKUP(A5,[5]深证成份指数历史数据!$A:$B,2,) -> 13264.37 | AA5: =VLOOKUP(A5,[6]台湾加权指数历史数据!$A:$B,2,) -> 8356.89 | AB5: 21654.16 | AC5: 2908.42 | AD5: 5252.2 | AE5: =VLOOKUP(A5,[7]越南VN30指数历史数据!$A:$B,2,) -> 528.89 | AF5: 25278.6 | AG5: 9953.17 | AH5: 10810.91 | AI5: 911.29 | AJ5: 1189.67
A6: 40195 | B6: 2331.6 | C6: 66220 | D6: 4750.6 | E6: 10172.98 | F6: 11343.43 | G6: 617.12 | H6: 1091.76 | I6: 2205.29 | J6: 30830.91 | K6: 17446.54 | L6: 2407.78 | M6: 5695.32 | N6: =VLOOKUP(A6,'[1]俄罗斯交易系统市值加权指数历史数据 (1)'!$A:$B,2,) -> 1489.46 | O6: 3820.78 | P6: 329.48 | Q6: 6493.96 | R6: 539.97 | S6: 11373.4 | T6: 5302.99 | U6: 2836.8 | V6: =VLOOKUP(A6,[2]韩国KOSPI指数历史数据!$A:$B,2,) -> 1684.35 | W6: =VLOOKUP(A6,[3]日经225指数历史数据!$A:$B,2,) -> 10590.55 | X6: 1155.62 | Y6: =VLOOKUP(A6,[4]上证指数历史数据!$A:$B,2,) -> 3128.59 | Z6: =VLOOKUP(A6,[5]深证成份指数历史数据!$A:$B,2,) -> 12595.93 | AA6: =VLOOKUP(A6,[6]台湾加权指数历史数据!$A:$B,2,) -> 7927.31 | AB6: 20726.18 | AC6: 2819.71 | AD6: 5036 | AE6: =VLOOKUP(A6,[7]越南VN30指数历史数据!$A:$B,2,) -> 503.64 | AF6: 24428.41 | AG6: 10237.75 | AH6: 10920.14 | AI6: 911.71 | AJ6: 1189.2
A7: 40202 | B7: 2298.55 | C7: 65402 | D7: 4569.6 | E7: 10067.33 | F7: 11094.31 | G7: 602.04 | H7: 1073.87 | I7: 2147.35 | J7: 30391.61 | K7: 17594.64 | L7: 2382.64 | M7: 5608.79 | N7: =VLOOKUP(A7,'[1]俄罗斯交易系统市值加权指数历史数据 (1)'!$A:$B,2,) -> 1473.81 | O7: 3739.46 | P7: 327.9 | Q7: 6440.72 | R7: 546.51 | S7: 10947.7 | T7: 5188.52 | U7: 2776.83 | V7: =VLOOKUP(A7,[2]韩国KOSPI指数历史数据!$A:$B,2,) -> 1602.43 | W7: =VLOOKUP(A7,[3]日经225指数历史数据!$A:$B,2,) -> 10198.04 | X7: 1135.79 | Y7: =VLOOKUP(A7,[4]上证指数历史数据!$A:$B,2,) -> 2989.29 | Z7: =VLOOKUP(A7,[5]深证成份指数历史数据!$A:$B,2,) -> 12137.2 | AA7: =VLOOKUP(A7,[6]台湾加权指数历史数据!$A:$B,2,) -> 7640.44 | AB7: 20121.99 | AC7: 2745.35 | AD7: 4882.05 | AE7: =VLOOKUP(A7,[7]越南VN30指数历史数据!$A:$B,2,) -> 504.97 | AF7: 24041.26 | AG7: 9983.67 | AH7: 10928.44 | AI7: 923.7 | AJ7: 1188.38
A8: 40209 | B8: 2165.15 | C8: 62763 | D8: 4514.1 | E8: 10012.23 | F8: 11223.12 | G8: 592.98 | H8: 1066.19 | I8: 2141.12 | J8: 30630.73 | K8: 17191.53 | L8: 2195.65 | M8: 5434.34 | N8: =VLOOKUP(A8,'[1]俄罗斯交易系统市值加权指数历史数据 (1)'!$A:$B,2,) -> 1411.14 | O8: 3563.76 | P8: 315.04 | Q8: 6264.33 | R8: 514.55 | S8: 10103.3 | T8: 5060.92 | U8: 2631.64 | V8: =VLOOKUP(A8,[2]韩国KOSPI指数历史数据!$A:$B,2,) -> 1567.12 | W8: =VLOOKUP(A8,[3]日经225指数历史数据!$A:$B,2,) -> 10057.09 | X8: 1135.17 | Y8: =VLOOKUP(A8,[4]上证指数历史数据!$A:$B,2,) -> 2939.4 | Z8: =VLOOKUP(A8,[5]深证成份指数历史数据!$A:$B,2,) -> 11917.14 | AA8: =VLOOKUP(A8,[6]台湾加权指数历史数据!$A:$B,2,) -> 7212.87 | AB8: 19665.08 | AC8: 2683.56 | AD8: 4718.65 | AE8: =VLOOKUP(A8,[7]越南VN30指数历史数据!$A:$B,2,) -> 521.39 | AF8: 23111.25 | AG8: 10409.92 | AH8: 10926.96 | AI8: 953.82 | AJ8: 1185.95
A9: 40216 | B9: 2273.41 | C9: 65855 | D9: 4562.1 | E9: 10099.14 | F9: 11469.81 | G9: 610.72 | H9: 1075.51 | I9: 2183.53 | J9: 31005.74 | K9: 17507.14 | L9: 2216.71 | M9: 5500.39 | N9: =VLOOKUP(A9,'[1]俄罗斯交易系统市值加权指数历史数据 (1)'!$A:$B,2,) -> 1363.83 | O9: 3599.07 | P9: 315.74 | Q9: 6416.2 | R9: 510.64 | S9: 10224.9 | T9: 5142.45 | U9: 2674.46 | V9: =VLOOKUP(A9,[2]韩国KOSPI指数历史数据!$A:$B,2,) -> 1593.66 | W9: =VLOOKUP(A9,[3]日经225指数历史数据!$A:$B,2,) -> 10092.19 | X9: 1136.46 | Y9: =VLOOKUP(A9,[4]上证指数历史数据!$A:$B,2,) -> 3018.13 | Z9: =VLOOKUP(A9,[5]深证成份指数历史数据!$A:$B,2,) -> 12304.78 | AA9: =VLOOKUP(A9,[6]台湾加权指数历史数据!$A:$B,2,) -> 7441.84 | AB9: 20268.69 | AC9: 2758.9 | AD9: 4826.85 | AE9: =VLOOKUP(A9,[7]越南VN30指数历史数据!$A:$B,2,) -> 535.8 | AF9: 23569.11 | AG9: 10357.91 | AH9: 11097.27 | AI9: 958.16 | AJ9: 1177.88
A10: 40223 | B10: 2334.99 | C10: 67597 | D10: 4635.1 | E10: 10402.35 | F10: 11709.29 | G10: 631.62 | H10: 1109.17 | I10: 2243.87 | J10: 32172.11 | K10: 17823.69 | L10: 2249.48 | M10: 5722.05 | N10: =VLOOKUP(A10,'[1]俄罗斯交易系统市值加权指数历史数据 (1)'!$A:$B,2,) -> 1423.13 | O10: 3769.54 | P10: 325.6 | Q10: 6709.68 | R10: 533.19 | S10: 10676.7 | T10: 5358.17 | U10: 2793.37 | V10: =VLOOKUP(A10,[2]韩国KOSPI指数历史数据!$A:$B,2,) -> 1593.9 | W10: =VLOOKUP(A10,[3]日经225指数历史数据!$A:$B,2,) -> 10123.58 | X10: 1165.96 | Y10: =VLOOKUP(A10,[4]上证指数历史数据!$A:$B,2,) -> #N/A | Z10: =VLOOKUP(A10,[5]深证成份指数历史数据!$A:$B,2,) -> #N/A | AA10: =VLOOKUP(A10,[6]台湾加权指数历史数据!$A:$B,2,) -> #N/A | AB10: 19894.02 | AC10: 2757.14 | AD10: 4844.9 | AE10: =VLOOKUP(A10,[7]越南VN30指数历史数据!$A:$B,2,) -> #N/A | AF10: 24352.61 | AG10: 10254.07 | AH10: 11053.55 | AI10: 966.11 | AJ10: 1181.9
A11: 40230 | B11: 2221.38 | C11: 66503 | D11: 4637.7 | E11: 10325.26 | F11: 11629.63 | G11: 628.56 | H11: 1104.49 | I11: 2238.26 | J11: 31634.54 | K11: 17789.25 | L11: 2265.01 | M11: 5598.46 | N11: =VLOOKUP(A11,'[1]俄罗斯交易系统市值加权指数历史数据 (1)'!$A:$B,2,) -> 1390.25 | O11: 3708.8 | P11: 317.74 | Q11: 6710.99 | R11: 497.05 | S11: 10333.6 | T11: 5354.52 | U11: 2728.47 | V11: =VLOOKUP(A11,[2]韩国KOSPI指数历史数据!$A:$B,2,) -> 1594.58 | W11: =VLOOKUP(A11,[3]日经225指数历史数据!$A:$B,2,) -> 10126.03 | X11: 1159.61 | Y11: =VLOOKUP(A11,[4]上证指数历史数据!$A:$B,2,) -> 3051.94 | Z11: =VLOOKUP(A11,[5]深证成份指数历史数据!$A:$B,2,) -> 12436.66 | AA11: =VLOOKUP(A11,[6]台湾加权指数历史数据!$A:$B,2,) -> 7436.1 | AB11: 20608.7 | AC11: 2750.86 | AD11: 4922.3 | AE11: =VLOOKUP(A11,[7]越南VN30指数历史数据!$A:$B,2,) -> 517.02 | AF11: 23994.59 | AG11: 10053.68 | AH11: 11096.8 | AI11: 956.18 | AJ11: 1181.9
A12: 40237 | B12: 2298.74 | C12: 68847 | D12: 4767.2 | E12: 10566.2 | F12: 11975.14 | G12: 666.02 | H12: 1138.7 | I12: 2326.35 | J12: 32436.53 | K12: 17632.64 | L12: 2389.37 | M12: 5877.36 | N12: =VLOOKUP(A12,'[1]俄罗斯交易系统市值加权指数历史数据 (1)'!$A:$B,2,) -> 1508.21 | O12: 3910.42 | P12: 338.68 | Q12: 6847.78 | R12: 526.26 | S12: 11019.8 | T12: 5599.76 | U12: 2877.44 | V12: =VLOOKUP(A12,[2]韩国KOSPI指数历史数据!$A:$B,2,) -> 1634.57 | W12: =VLOOKUP(A12,[3]日经225指数历史数据!$A:$B,2,) -> 10368.96 | X12: 1207.63 | Y12: =VLOOKUP(A12,[4]上证指数历史数据!$A:$B,2,) -> 3031.07 | Z12: =VLOOKUP(A12,[5]深证成份指数历史数据!$A:$B,2,) -> 12341.74 | AA12: =VLOOKUP(A12,[6]台湾加权指数历史数据!$A:$B,2,) -> 7666.26 | AB12: 20787.97 | AC12: 2790.29 | AD12: 5088.7 | AE12: =VLOOKUP(A12,[7]越南VN30指数历史数据!$A:$B,2,) -> 538.84 | AF12: 25058.42 | AG12: 10156.82 | AH12: 10985.17 | AI12: 956.98 | AJ12: 1181.86
A13: 40244 | B13: 2359.97 | C13: 69341 | D13: 4818.1 | E13: 10624.69 | F13: 12013.82 | G13: 676.59 | H13: 1149.99 | I13: 2367.66 | J13: 32578.05 | K13: 17819.13 | L13: 2415.82 | M13: 5945.11 | N13: =VLOOKUP(A13,'[1]俄罗斯交易系统市值加权指数历史数据 (1)'!$A:$B,2,) -> 1534.68 | O13: 3927.4 | P13: 339.57 | Q13: 6836.6 | R13: 522.33 | S13: 11077 | T13: 5625.65 | U13: 2898.36 | V13: =VLOOKUP(A13,[2]韩国KOSPI指数历史数据!$A:$B,2,) -> 1662.74 | W13: =VLOOKUP(A13,[3]日经225指数历史数据!$A:$B,2,) -> 10751.26 | X13: 1209.4 | Y13: =VLOOKUP(A13,[4]上证指数历史数据!$A:$B,2,) -> 3013.41 | Z13: =VLOOKUP(A13,[5]深证成份指数历史数据!$A:$B,2,) -> 12169.11 | AA13: =VLOOKUP(A13,[6]台湾加权指数历史数据!$A:$B,2,) -> 7748.33 | AB13: 21209.74 | AC13: 2881.36 | AD13: 5137 | AE13: =VLOOKUP(A13,[7]越南VN30指数历史数据!$A:$B,2,) -> 561.36 | AF13: 25373.37 | AG13: 10131.59 | AH13: 11021.88 | AI13: 1008.08 | AJ13: 1179.88
A14: 40251 | B14: 2381.1 | C14: 68829 | D14: 4872.2 | E14: 10741.98 | F14: 11947.98 | G14: 673.89 | H14: 1159.9 | I14: 2374.41 | J14: 33022.84 | K14: 17627.22 | L14: 2441.39 | M14: 5982.43 | N14: =VLOOKUP(A14,'[1]俄罗斯交易系统市值加权指数历史数据 (1)'!$A:$B,2,) -> 1544.71 | O14: 3925.44 | P14: 338.65 | Q14: 6880.76 | R14: 534.37 | S14: 10990.8 | T14: 5650.12 | U14: 2897.95 | V14: =VLOOKUP(A14,[2]韩国KOSPI指数历史数据!$A:$B,2,) -> 1686.11 | W14: =VLOOKUP(A14,[3]日经225指数历史数据!$A:$B,2,) -> 10824.72 | X14: 1214.93 | Y14: =VLOOKUP(A14,[4]上证指数历史数据!$A:$B,2,) -> 3067.75 | Z14: =VLOOKUP(A14,[5]深证成份指数历史数据!$A:$B,2,) -> 12352.92 | AA14: =VLOOKUP(A14,[6]台湾加权指数历史数据!$A:$B,2,) -> 7897.91 | AB14: 21370.82 | AC14: 2915.7 | AD14: 5262.8 | AE14: =VLOOKUP(A14,[7]越南VN30指数历史数据!$A:$B,2,) -> 542.82 | AF14: 25667.58 | AG14: 9874.14 | AH14: 10984.99 | AI14: 1021.99 | AJ14: 1177.13
A15: 40258 | B15: 2402.45 | C15: 68683 | D15: 4896.9 | E15: 10850.36 | F15: 11957.37 | G15: 678.97 | H15: 1166.59 | I15: 2395.13 | J15: 33147.81 | K15: 17582.47 | L15: 2495.65 | M15: 6120.05 | N15: =VLOOKUP(A15,'[1]俄罗斯交易系统市值加权指数历史数据 (1)'!$A:$B,2,) -> 1519.87 | O15: 3988.93 | P15: 343.81 | Q15: 6838.95 | R15: 566.11 | S15: 11071.1 | T15: 5703.02 | U15: 2940.94 | V15: =VLOOKUP(A15,[2]韩国KOSPI指数历史数据!$A:$B,2,) -> 1697.72 | W15: =VLOOKUP(A15,[3]日经225指数历史数据!$A:$B,2,) -> 10996.37 | X15: 1231.3 | Y15: =VLOOKUP(A15,[4]上证指数历史数据!$A:$B,2,) -> 3059.72 | Z15: =VLOOKUP(A15,[5]深证成份指数历史数据!$A:$B,2,) -> 12240.36 | AA15: =VLOOKUP(A15,[6]台湾加权指数历史数据!$A:$B,2,) -> 7876.86 | AB15: 21053.11 | AC15: 2906.28 | AD15: 5282 | AE15: =VLOOKUP(A15,[7]越南VN30指数历史数据!$A:$B,2,) -> 530.84 | AF15: 25663.36 | AG15: 10097.94 | AH15: 11228.49 | AI15: 1024.79 | AJ15: 1177.09
A16: 40265 | B16: 2373.71 | C16: 71136 | D16: 4907.7 | E16: 10927.07 | F16: 12151.06 | G16: 683.98 | H16: 1178.1 | I16: 2402.58 | J16: 33266.43 | K16: 17773.8 | L16: 2552.5 | M16: 6235.56 | N16: =VLOOKUP(A16,'[1]俄罗斯交易系统市值加权指数历史数据 (1)'!$A:$B,2,) -> 1614.45 | O16: 4034.23 | P16: 351.44 | Q16: 6888.92 | R16: 580.6 | S16: 11067.9 | T16: 5744.89 | U16: 2978.5 | V16: =VLOOKUP(A16,[2]韩国KOSPI指数历史数据!$A:$B,2,) -> 1723.49 | W16: =VLOOKUP(A16,[3]日经225指数历史数据!$A:$B,2,) -> 11286.09 | X16: 1233.3 | Y16: =VLOOKUP(A16,[4]上证指数历史数据!$A:$B,2,) -> 3157.96 | Z16: =VLOOKUP(A16,[5]深证成份指数历史数据!$A:$B,2,) -> 12767.86 | AA16: =VLOOKUP(A16,[6]台湾加权指数历史数据!$A:$B,2,) -> 8025.93 | AB16: 21537 | AC16: 2943.02 | AD16: 5290.5 | AE16: =VLOOKUP(A16,[7]越南VN30指数历史数据!$A:$B,2,) -> 534.26 | AF16: 26113.3 | AG16: 10238.53 | AH16: 11353.56 | AI16: 1048.12 | AJ16: 1174.85
A17: 40272 | B17: 2487.76 | C17: 71417 | D17: 4948.1 | E17: 10997.35 | F17: 12176.84 | G17: 702.95 | H17: 1194.37 | I17: 2454.05 | J17: 33840.85 | K17: 17942.86 | L17: 2553.58 | M17: 6249.7 | N17: =VLOOKUP(A17,'[1]俄罗斯交易系统市值加权指数历史数据 (1)'!$A:$B,2,) -> 1631.81 | O17: 4050.54 | P17: 355.89 | Q17: 6888.97 | R17: 591.85 | S17: 11394.2 | T17: 5770.98 | U17: 2993.54 | V17: =VLOOKUP(A17,[2]韩国KOSPI指数历史数据!$A:$B,2,) -> 1724.47 | W17: =VLOOKUP(A17,[3]日经225指数历史数据!$A:$B,2,) -> 11204.34 | X17: 1212.02 | Y17: =VLOOKUP(A17,[4]上证指数历史数据!$A:$B,2,) -> 3145.35 | Z17: =VLOOKUP(A17,[5]深证成份指数历史数据!$A:$B,2,) -> 12555.12 | AA17: =VLOOKUP(A17,[6]台湾加权指数历史数据!$A:$B,2,) -> 8092.03 | AB17: 22208.5 | AC17: 2971.97 | AD17: 5361.75 | AE17: =VLOOKUP(A17,[7]越南VN30指数历史数据!$A:$B,2,) -> 540.28 | AF17: 26368.35 | AG17: 10821.14 | AH17: 11394.1 | AI17: 1122.61 | AJ17: 1173.45
A18: 40279 | B18: 2398.94 | C18: 69421 | D18: 4984.7 | E18: 11018.66 | F18: 12070.66 | G18: 714.62 | H18: 1192.13 | I18: 2481.26 | J18: 33621.39 | K18: 17790.81 | L18: 2594.83 | M18: 6180.9 | N18: =VLOOKUP(A18,'[1]俄罗斯交易系统市值加权指数历史数据 (1)'!$A:$B,2,) -> 1642.57 | O18: 3986.63 | P18: 349.75 | Q18: 6893.69 | R18: 582.24 | S18: 11259.7 | T18: 5743.96 | U18: 2949.65 | V18: =VLOOKUP(A18,[2]韩国KOSPI指数历史数据!$A:$B,2,) -> 1734.49 | W18: =VLOOKUP(A18,[3]日经225指数历史数据!$A:$B,2,) -> 11102.18 | X18: 1215.01 | Y18: =VLOOKUP(A18,[4]上证指数历史数据!$A:$B,2,) -> 3130.3 | Z18: =VLOOKUP(A18,[5]深证成份指数历史数据!$A:$B,2,) -> 12416.86 | AA18: =VLOOKUP(A18,[6]台湾加权指数历史数据!$A:$B,2,) -> 8111.57 | AB18: 21865.26 | AC18: 3007.19 | AD18: 5262.6 | AE18: =VLOOKUP(A18,[7]越南VN30指数历史数据!$A:$B,2,) -> 541.88 | AF18: 26058.05 | AG18: 11298.93 | AH18: 11966.51 | AI18: 1140.44 | AJ18: 1168.08
A19: 40286 | B19: 2447.03 | C19: 69509 | D19: 4881.5 | E19: 11204.28 | F19: 12239.64 | G19: 741.92 | H19: 1217.28 | I19: 2530.15 | J19: 33853.69 | K19: 17929.26 | L19: 2514.63 | M19: 6259.53 | N19: =VLOOKUP(A19,'[1]俄罗斯交易系统市值加权指数历史数据 (1)'!$A:$B,2,) -> 1602.99 | O19: 3951.3 | P19: 353.38 | Q19: 6767.97 | R19: 583.38 | S19: 10918.2 | T19: 5723.65 | U19: 2918.11 | V19: =VLOOKUP(A19,[2]韩国KOSPI指数历史数据!$A:$B,2,) -> 1737.03 | W19: =VLOOKUP(A19,[3]日经225指数历史数据!$A:$B,2,) -> 10914.46 | X19: 1199.63 | Y19: =VLOOKUP(A19,[4]上证指数历史数据!$A:$B,2,) -> 2983.54 | Z19: =VLOOKUP(A19,[5]深证成份指数历史数据!$A:$B,2,) -> 11702.87 | AA19: =VLOOKUP(A19,[6]台湾加权指数历史数据!$A:$B,2,) -> 8004.89 | AB19: 21244.49 | AC19: 2988.49 | AD19: 5304.1 | AE19: =VLOOKUP(A19,[7]越南VN30指数历史数据!$A:$B,2,) -> 551.44 | AF19: 25906.7 | AG19: 11153.45 | AH19: 12135.52 | AI19: 1123.03 | AJ19: 1167.56
A20: 40293 | B20: 2396.27 | C20: 67530 | D20: 4807.4 | E20: 11008.61 | F20: 12210.7 | G20: 716.6 | H20: 1186.69 | I20: 2461.19 | J20: 32687.32 | K20: 18039.09 | L20: 2547.52 | M20: 6135.7 | N20: =VLOOKUP(A20,'[1]俄罗斯交易系统市值加权指数历史数据 (1)'!$A:$B,2,) -> 1572.84 | O20: 3816.99 | P20: 345.91 | Q20: 6616.82 | R20: 589.59 | S20: 10492.2 | T20: 5553.29 | U20: 2816.86 | V20: =VLOOKUP(A20,[2]韩国KOSPI指数历史数据!$A:$B,2,) -> 1741.56 | W20: =VLOOKUP(A20,[3]日经225指数历史数据!$A:$B,2,) -> 11057.4 | X20: 1164.23 | Y20: =VLOOKUP(A20,[4]上证指数历史数据!$A:$B,2,) -> 2870.61 | Z20: =VLOOKUP(A20,[5]深证成份指数历史数据!$A:$B,2,) -> 11162.54 | AA20: =VLOOKUP(A20,[6]台湾加权指数历史数据!$A:$B,2,) -> 8004.25 | AB20: 21108.59 | AC20: 2974.61 | AD20: 5278 | AE20: =VLOOKUP(A20,[7]越南VN30指数历史数据!$A:$B,2,) -> 560.62 | AF20: 25629.93 | AG20: 11127.16 | AH20: 12286.99 | AI20: 1085.57 | AJ20: 1167.47
A21: 40300 | B21: 2160.2 | C21: 62871 | D21: 4480.7 | E21: 10380.43 | F21: 11692.43 | G21: 653 | H21: 1110.88 | I21: 2265.64 | J21: 31488.82 | K21: 17639.48 | L21: 2336.99 | M21: 5715.09 | N21: =VLOOKUP(A21,'[1]俄罗斯交易系统市值加权指数历史数据 (1)'!$A:$B,2,) -> 1369.91 | O21: 3392.59 | P21: 312.35 | Q21: 6205.63 | R21: 526.87 | S21: 9046.1 | T21: 5123.02 | U21: 2500.18 | V21: =VLOOKUP(A21,[2]韩国KOSPI指数历史数据!$A:$B,2,) -> 1647.5 | W21: =VLOOKUP(A21,[3]日经225指数历史数据!$A:$B,2,) -> 10364.59 | X21: 1140.61 | Y21: =VLOOKUP(A21,[4]上证指数历史数据!$A:$B,2,) -> 2688.38 | Z21: =VLOOKUP(A21,[5]深证成份指数历史数据!$A:$B,2,) -> 10146.42 | AA21: =VLOOKUP(A21,[6]台湾加权指数历史数据!$A:$B,2,) -> 7567.1 | AB21: 19920.29 | AC21: 2821.11 | AD21: 5018.05 | AE21: =VLOOKUP(A21,[7]越南VN30指数历史数据!$A:$B,2,) -> 555.2 | AF21: 23598.02 | AG21: 10621.01 | AH21: 12171.89 | AI21: 1126.67 | AJ21: 1167.59
A22: 40307 | B22: 2212.87 | C22: 63412 | D22: 4611.1 | E22: 10620.16 | F22: 12014.97 | G22: 693.98 | H22: 1135.68 | I22: 2346.85 | J22: 31812.73 | K22: 17958.89 | L22: 2389.61 | M22: 6056.71 | N22: =VLOOKUP(A22,'[1]俄罗斯交易系统市值加权指数历史数据 (1)'!$A:$B,2,) -> 1441.68 | O22: 3560.36 | P22: 327.24 | Q22: 6428.68 | R22: 557.48 | S22: 9314.7 | T22: 5262.85 | U22: 2633.92 | V22: =VLOOKUP(A22,[2]韩国KOSPI指数历史数据!$A:$B,2,) -> 1695.63 | W22: =VLOOKUP(A22,[3]日经225指数历史数据!$A:$B,2,) -> 10462.51 | X22: 1154.62 | Y22: =VLOOKUP(A22,[4]上证指数历史数据!$A:$B,2,) -> 2696.63 | Z22: =VLOOKUP(A22,[5]深证成份指数历史数据!$A:$B,2,) -> 10330.14 | AA22: =VLOOKUP(A22,[6]台湾加权指数历史数据!$A:$B,2,) -> 7772.13 | AB22: 20145.43 | AC22: 2855.21 | AD22: 5093.5 | AE22: =VLOOKUP(A22,[7]越南VN30指数历史数据!$A:$B,2,) -> 537.83 | AF22: 24355.07 | AG22: 10314.21 | AH22: 12294.67 | AI22: 1133.37 | AJ22: 1170.63
A23: 40314 | B23: 2123.62 | C23: 60259 | D23: 4305.4 | E23: 10193.39 | F23: 11521.35 | G23: 649.29 | H23: 1087.69 | I23: 2229.04 | J23: 30629.15 | K23: 17712.66 | L23: 2308.92 | M23: 5829.25 | N23: =VLOOKUP(A23,'[1]俄罗斯交易系统市值加权指数历史数据 (1)'!$A:$B,2,) -> 1297.91 | O23: 3430.74 | P23: 313.41 | Q23: 6206.59 | R23: 541.12 | S23: 9407.3 | T23: 5062.93 | U23: 2574.18 | V23: =VLOOKUP(A23,[2]韩国KOSPI指数历史数据!$A:$B,2,) -> 1600.18 | W23: =VLOOKUP(A23,[3]日经225指数历史数据!$A:$B,2,) -> 9784.54 | X23: 1101.45 | Y23: =VLOOKUP(A23,[4]上证指数历史数据!$A:$B,2,) -> 2583.52 | Z23: =VLOOKUP(A23,[5]深证成份指数历史数据!$A:$B,2,) -> 10209.07 | AA23: =VLOOKUP(A23,[6]台湾加权指数历史数据!$A:$B,2,) -> 7237.71 | AB23: 19545.83 | AC23: 2701.2 | AD23: 4931.15 | AE23: =VLOOKUP(A23,[7]越南VN30指数历史数据!$A:$B,2,) -> 496.24 | AF23: 23349.1 | AG23: 9556.98 | AH23: 12370.36 | AI23: 1113.63 | AJ23: 1173.31
A24: 40321 | B24: 2168.57 | C24: 61947 | D24: 4457.5 | E24: 10136.63 | F24: 11671.44 | G24: 661.61 | H24: 1089.41 | I24: 2257.04 | J24: 31547.55 | K24: 17924.45 | L24: 2427.11 | M24: 5946.18 | N24: =VLOOKUP(A24,'[1]俄罗斯交易系统市值加权指数历史数据 (1)'!$A:$B,2,) -> 1366.9 | O24: 3515.06 | P24: 320.64 | Q24: 6321.92 | R24: 552.34 | S24: 9425.5 | T24: 5188.43 | U24: 2614.06 | V24: =VLOOKUP(A24,[2]韩国KOSPI指数历史数据!$A:$B,2,) -> 1622.78 | W24: =VLOOKUP(A24,[3]日经225指数历史数据!$A:$B,2,) -> 9762.98 | X24: 1106.45 | Y24: =VLOOKUP(A24,[4]上证指数历史数据!$A:$B,2,) -> 2655.77 | Z24: =VLOOKUP(A24,[5]深证成份指数历史数据!$A:$B,2,) -> 10495.65 | AA24: =VLOOKUP(A24,[6]台湾加权指数历史数据!$A:$B,2,) -> 7295.32 | AB24: 19766.71 | AC24: 2739.7 | AD24: 5066.55 | AE24: =VLOOKUP(A24,[7]越南VN30指数历史数据!$A:$B,2,) -> 527.32 | AF24: 24218.98 | AG24: 9422.15 | AH24: 11990.24 | AI24: 1091.42 | AJ24: 1173.15
A25: 40328 | B25: 2181.21 | C25: 61676 | D25: 4449.4 | E25: 9931.97 | F25: 11569.61 | G25: 633.97 | H25: 1064.88 | I25: 2219.17 | J25: 30992.65 | K25: 18056.96 | L25: 2354.86 | M25: 5938.88 | N25: =VLOOKUP(A25,'[1]俄罗斯交易系统市值加权指数历史数据 (1)'!$A:$B,2,) -> 1360.74 | O25: 3455.61 | P25: 321.22 | Q25: 6298.97 | R25: 546.13 | S25: 8923.4 | T25: 5126 | U25: 2553.59 | V25: =VLOOKUP(A25,[2]韩国KOSPI指数历史数据!$A:$B,2,) -> 1664.13 | W25: =VLOOKUP(A25,[3]日经225指数历史数据!$A:$B,2,) -> 9901.19 | X25: 1097.38 | Y25: =VLOOKUP(A25,[4]上证指数历史数据!$A:$B,2,) -> 2553.59 | Z25: =VLOOKUP(A25,[5]深证成份指数历史数据!$A:$B,2,) -> 10187.2 | AA25: =VLOOKUP(A25,[6]台湾加权指数历史数据!$A:$B,2,) -> 7344.59 | AB25: 19780.07 | AC25: 2806.51 | AD25: 5135.5 | AE25: =VLOOKUP(A25,[7]越南VN30指数历史数据!$A:$B,2,) -> 523.78 | AF25: 23604.51 | AG25: 9699.75 | AH25: 12162.58 | AI25: 1086.25 | AJ25: 1173.15
A26: 40335 | B26: 2281.23 | C26: 63605 | D26: 4505.5 | E26: 10211.07 | F26: 11666.92 | G26: 649 | H26: 1091.6 | I26: 2243.6 | J26: 32124.28 | K26: 18456.52 | L26: 2378.4 | M26: 6047.83 | N26: =VLOOKUP(A26,'[1]俄罗斯交易系统市值加权指数历史数据 (1)'!$A:$B,2,) -> 1356.79 | O26: 3555.52 | P26: 325.56 | Q26: 6426.74 | R26: 551.32 | S26: 9561.7 | T26: 5163.68 | U26: 2638.31 | V26: =VLOOKUP(A26,[2]韩国KOSPI指数历史数据!$A:$B,2,) -> 1675.34 | W26: =VLOOKUP(A26,[3]日经225指数历史数据!$A:$B,2,) -> 9705.25 | X26: 1090.8 | Y26: =VLOOKUP(A26,[4]上证指数历史数据!$A:$B,2,) -> 2569.94 | Z26: =VLOOKUP(A26,[5]深证成份指数历史数据!$A:$B,2,) -> 10239.33 | AA26: =VLOOKUP(A26,[6]台湾加权指数历史数据!$A:$B,2,) -> 7299.49 | AB26: 19872.38 | AC26: 2796.29 | AD26: 5119.35 | AE26: =VLOOKUP(A26,[7]越南VN30指数历史数据!$A:$B,2,) -> 519.51 | AF26: 23888.31 | AG26: 9303.9 | AH26: 12290.23 | AI26: 1053.06 | AJ26: 1172.44
A27: 40342 | B27: 2320.36 | C27: 64438 | D27: 4551.9 | E27: 10450.64 | F27: 11927.59 | G27: 666.92 | H27: 1117.51 | I27: 2309.8 | J27: 32814.62 | K27: 19042.03 | L27: 2361.16 | M27: 6216.98 | N27: =VLOOKUP(A27,'[1]俄罗斯交易系统市值加权指数历史数据 (1)'!$A:$B,2,) -> 1409.43 | O27: 3687.21 | P27: 336.06 | Q27: 6447.06 | R27: 570.34 | S27: 9971.8 | T27: 5250.84 | U27: 2737.02 | V27: =VLOOKUP(A27,[2]韩国KOSPI指数历史数据!$A:$B,2,) -> 1711.95 | W27: =VLOOKUP(A27,[3]日经225指数历史数据!$A:$B,2,) -> 9995.02 | X27: 1105.05 | Y27: =VLOOKUP(A27,[4]上证指数历史数据!$A:$B,2,) -> 2513.22 | Z27: =VLOOKUP(A27,[5]深证成份指数历史数据!$A:$B,2,) -> 9966.54 | AA27: =VLOOKUP(A27,[6]台湾加权指数历史数据!$A:$B,2,) -> 7493.11 | AB27: 20286.71 | AC27: 2833.4 | AD27: 5262.6 | AE27: =VLOOKUP(A27,[7]越南VN30指数历史数据!$A:$B,2,) -> 526.57 | AF27: 24754.9 | AG27: 9552.91 | AH27: 12056.74 | AI27: 1080.77 | AJ27: 1172.74
A28: 40349 | B28: 2318.14 | C28: 64824 | D28: 4413 | E28: 10143.81 | F28: 11707.85 | G28: 645.11 | H28: 1076.76 | I28: 2223.48 | J28: 32607.13 | K28: 19071.34 | L28: 2337.98 | M28: 6070.6 | N28: =VLOOKUP(A28,'[1]俄罗斯交易系统市值加权指数历史数据 (1)'!$A:$B,2,) -> 1387.66 | O28: 3519.73 | P28: 325.99 | Q28: 6275.35 | R28: 558.64 | S28: 9535 | T28: 5046.47 | U28: 2629.25 | V28: =VLOOKUP(A28,[2]韩国KOSPI指数历史数据!$A:$B,2,) -> 1729.84 | W28: =VLOOKUP(A28,[3]日经225指数历史数据!$A:$B,2,) -> 9737.48 | X28: 1093.65 | Y28: =VLOOKUP(A28,[4]上证指数历史数据!$A:$B,2,) -> 2552.82 | Z28: =VLOOKUP(A28,[5]深证成份指数历史数据!$A:$B,2,) -> 10104.83 | AA28: =VLOOKUP(A28,[6]台湾加权指数历史数据!$A:$B,2,) -> 7474.71 | AB28: 20690.79 | AC28: 2851.64 | AD28: 5269.05 | AE28: =VLOOKUP(A28,[7]越南VN30指数历史数据!$A:$B,2,) -> 519.8 | AF28: 24263.82 | AG28: 9384.6 | AH28: 12014.97 | AI28: 1041.85 | AJ28: 1174.36
A29: 40356 | B29: 2217.08 | C29: 61430 | D29: 4238.7 | E29: 9686.48 | F29: 11196.06 | G29: 598.97 | H29: 1022.58 | I29: 2091.79 | J29: 31379.67 | K29: 18832.91 | L29: 2300.67 | M29: 5834.15 | N29: =VLOOKUP(A29,'[1]俄罗斯交易系统市值加权指数历史数据 (1)'!$A:$B,2,) -> 1316.65 | O29: 3348.37 | P29: 308.2 | Q29: 5974.3 | R29: 556.36 | S29: 9250.8 | T29: 4838.09 | U29: 2522.36 | V29: =VLOOKUP(A29,[2]韩国KOSPI指数历史数据!$A:$B,2,) -> 1671.82 | W29: =VLOOKUP(A29,[3]日经225指数历史数据!$A:$B,2,) -> 9203.71 | X29: 1061.56 | Y29: =VLOOKUP(A29,[4]上证指数历史数据!$A:$B,2,) -> 2382.9 | Z29: =VLOOKUP(A29,[5]深证成份指数历史数据!$A:$B,2,) -> 9227.89 | AA29: =VLOOKUP(A29,[6]台湾加权指数历史数据!$A:$B,2,) -> 7330.74 | AB29: 19905.32 | AC29: 2844.19 | AD29: 5237.1 | AE29: =VLOOKUP(A29,[7]越南VN30指数历史数据!$A:$B,2,) -> 519.6 | AF29: 23355.16 | AG29: 8968.17 | AH29: 11785.96 | AI29: 1054.26 | AJ29: 1170.69
A30: 40363 | B30: 2289.5 | C30: 63476 | D30: 4396.3 | E30: 10198.03 | F30: 11570.45 | G30: 629.43 | H30: 1077.96 | I30: 2196.45 | J30: 32004.31 | K30: 19342.85 | L30: 2333.6 | M30: 6065.24 | N30: =VLOOKUP(A30,'[1]俄罗斯交易系统市值加权指数历史数据 (1)'!$A:$B,2,) -> 1359.45 | O30: 3554.48 | P30: 324.42 | Q30: 6210.49 | R30: 571.51 | S30: 10127.3 | T30: 5132.94 | U30: 2681.2 | V30: =VLOOKUP(A30,[2]韩国KOSPI指数历史数据!$A:$B,2,) -> 1723.01 | W30: =VLOOKUP(A30,[3]日经225指数历史数据!$A:$B,2,) -> 9585.32 | X30: 1090.15 | Y30: =VLOOKUP(A30,[4]上证指数历史数据!$A:$B,2,) -> 2470.92 | Z30: =VLOOKUP(A30,[5]深证成份指数历史数据!$A:$B,2,) -> 9816.85 | AA30: =VLOOKUP(A30,[6]台湾加权指数历史数据!$A:$B,2,) -> 7647.25 | AB30: 20378.66 | AC30: 2917.17 | AD30: 5352.45 | AE30: =VLOOKUP(A30,[7]越南VN30指数历史数据!$A:$B,2,) -> 514.84 | AF30: 24284.88 | AG30: 8944.99 | AH30: 11739.71 | AI30: 1033.49 | AJ30: 1172.06
A31: 40370 | B31: 2283.07 | C31: 62339 | D31: 4422.7 | E31: 10097.9 | F31: 11569.65 | G31: 610.39 | H31: 1064.88 | I31: 2179.05 | J31: 31783.39 | K31: 19553.33 | L31: 2375.24 | M31: 6040.27 | N31: =VLOOKUP(A31,'[1]俄罗斯交易系统市值加权指数历史数据 (1)'!$A:$B,2,) -> 1389.92 | O31: 3500.16 | P31: 323.99 | Q31: 6184.37 | R31: 577.29 | S31: 9991.7 | T31: 5158.85 | U31: 2645.61 | V31: =VLOOKUP(A31,[2]韩国KOSPI指数历史数据!$A:$B,2,) -> 1738.45 | W31: =VLOOKUP(A31,[3]日经225指数历史数据!$A:$B,2,) -> 9408.36 | X31: 1111.31 | Y31: =VLOOKUP(A31,[4]上证指数历史数据!$A:$B,2,) -> 2424.27 | Z31: =VLOOKUP(A31,[5]深证成份指数历史数据!$A:$B,2,) -> 9806.64 | AA31: =VLOOKUP(A31,[6]台湾加权指数历史数据!$A:$B,2,) -> 7664.57 | AB31: 20250.16 | AC31: 2957.72 | AD31: 5393.9 | AE31: =VLOOKUP(A31,[7]越南VN30指数历史数据!$A:$B,2,) -> 521.45 | AF31: 24465.49 | AG31: 8980.42 | AH31: 11846.22 | AI31: 1058 | AJ31: 1170.05
A32: 40377 | B32: 2375.2 | C32: 66323 | D32: 4458.4 | E32: 10424.62 | F32: 11714.21 | G32: 650.65 | H32: 1102.66 | I32: 2269.47 | J32: 32806.03 | K32: 20026.73 | L32: 2460.96 | M32: 6166.34 | N32: =VLOOKUP(A32,'[1]俄罗斯交易系统市值加权指数历史数据 (1)'!$A:$B,2,) -> 1449.19 | O32: 3607.05 | P32: 337.14 | Q32: 6201.25 | R32: 593 | S32: 10388.2 | T32: 5312.62 | U32: 2719.13 | V32: =VLOOKUP(A32,[2]韩国KOSPI指数历史数据!$A:$B,2,) -> 1758.06 | W32: =VLOOKUP(A32,[3]日经225指数历史数据!$A:$B,2,) -> 9430.96 | X32: 1118.51 | Y32: =VLOOKUP(A32,[4]上证指数历史数据!$A:$B,2,) -> 2572.03 | Z32: =VLOOKUP(A32,[5]深证成份指数历史数据!$A:$B,2,) -> 10527.94 | AA32: =VLOOKUP(A32,[6]台湾加权指数历史数据!$A:$B,2,) -> 7761.22 | AB32: 20815.33 | AC32: 2973.47 | AD32: 5449.1 | AE32: =VLOOKUP(A32,[7]越南VN30指数历史数据!$A:$B,2,) -> 515.39 | AF32: 25333.32 | AG32: 8945.14 | AH32: 11857.08 | AI32: 1068.93 | AJ32: 1171.35
A33: 40384 | B33: 2394.16 | C33: 67515 | D33: 4493.5 | E33: 10465.94 | F33: 11713.43 | G33: 650.89 | H33: 1101.6 | I33: 2254.7 | J33: 32308.74 | K33: 20296.63 | L33: 2474.67 | M33: 6147.97 | N33: =VLOOKUP(A33,'[1]俄罗斯交易系统市值加权指数历史数据 (1)'!$A:$B,2,) -> 1479.73 | O33: 3643.14 | P33: 330.64 | Q33: 6200.78 | R33: 598.67 | S33: 10499.8 | T33: 5258.02 | U33: 2742.14 | V33: =VLOOKUP(A33,[2]韩国KOSPI指数历史数据!$A:$B,2,) -> 1759.33 | W33: =VLOOKUP(A33,[3]日经225指数历史数据!$A:$B,2,) -> 9537.3 | X33: 1118.59 | Y33: =VLOOKUP(A33,[4]上证指数历史数据!$A:$B,2,) -> 2637.5 | Z33: =VLOOKUP(A33,[5]深证成份指数历史数据!$A:$B,2,) -> 10785.35 | AA33: =VLOOKUP(A33,[6]台湾加权指数历史数据!$A:$B,2,) -> 7760.63 | AB33: 21029.81 | AC33: 2987.7 | AD33: 5367.6 | AE33: =VLOOKUP(A33,[7]越南VN30指数历史数据!$A:$B,2,) -> 512.21 | AF33: 25224.6 | AG33: 9357.21 | AH33: 11782.52 | AI33: 1112.26 | AJ33: 1171.15
A34: 40391 | B34: 2425.33 | C34: 68095 | D34: 4566.1 | E34: 10653.56 | F34: 11799.97 | G34: 650.68 | H34: 1121.64 | I34: 2288.47 | J34: 32917.92 | K34: 20807.99 | L34: 2548.63 | M34: 6259.63 | N34: =VLOOKUP(A34,'[1]俄罗斯交易系统市值加权指数历史数据 (1)'!$A:$B,2,) -> 1509.85 | O34: 3716.05 | P34: 331.19 | Q34: 6321.36 | R34: 597.53 | S34: 10651.1 | T34: 5332.39 | U34: 2779.34 | V34: =VLOOKUP(A34,[2]韩国KOSPI指数历史数据!$A:$B,2,) -> 1783.83 | W34: =VLOOKUP(A34,[3]日经225指数历史数据!$A:$B,2,) -> 9642.12 | X34: 1149.6 | Y34: =VLOOKUP(A34,[4]上证指数历史数据!$A:$B,2,) -> 2658.39 | Z34: =VLOOKUP(A34,[5]深证成份指数历史数据!$A:$B,2,) -> 10942.93 | AA34: =VLOOKUP(A34,[6]台湾加权指数历史数据!$A:$B,2,) -> 7963.3 | AB34: 21678.8 | AC34: 2995.06 | AD34: 5439.25 | AE34: =VLOOKUP(A34,[7]越南VN30指数历史数据!$A:$B,2,) -> 501.78 | AF34: 25172.71 | AG34: 9501.36 | AH34: 11761.11 | AI34: 1119.41 | AJ34: 1172.44
A35: 40398 | B35: 2367.98 | C35: 66264 | D35: 4459.6 | E35: 10303.15 | F35: 11528.25 | G35: 609.49 | H35: 1079.25 | I35: 2173.48 | J35: 32099.75 | K35: 20848.3 | L35: 2452.05 | M35: 6110.41 | N35: =VLOOKUP(A35,'[1]俄罗斯交易系统市值加权指数历史数据 (1)'!$A:$B,2,) -> 1445.37 | O35: 3610.91 | P35: 323.92 | Q35: 6294.34 | R35: 584.8 | S35: 10275.8 | T35: 5275.44 | U35: 2708.73 | V35: =VLOOKUP(A35,[2]韩国KOSPI指数历史数据!$A:$B,2,) -> 1746.24 | W35: =VLOOKUP(A35,[3]日经225指数历史数据!$A:$B,2,) -> 9253.46 | X35: 1140.26 | Y35: =VLOOKUP(A35,[4]上证指数历史数据!$A:$B,2,) -> 2606.7 | Z35: =VLOOKUP(A35,[5]深证成份指数历史数据!$A:$B,2,) -> 10886.57 | AA35: =VLOOKUP(A35,[6]台湾加权指数历史数据!$A:$B,2,) -> 7891.58 | AB35: 21071.57 | AC35: 2939.97 | AD35: 5452.1 | AE35: =VLOOKUP(A35,[7]越南VN30指数历史数据!$A:$B,2,) -> 469.15 | AF35: 24424.34 | AG35: 9397.1 | AH35: 11628.28 | AI35: 1077.53 | AJ35: 1172.68
A36: 40405 | B36: 2438.97 | C36: 66677 | D36: 4430.9 | E36: 10213.62 | F36: 11722.07 | G36: 610.78 | H36: 1071.69 | I36: 2179.76 | J36: 32291.67 | K36: 21124.9 | L36: 2445.14 | M36: 6005.16 | N36: =VLOOKUP(A36,'[1]俄罗斯交易系统市值加权指数历史数据 (1)'!$A:$B,2,) -> 1425.03 | O36: 3526.12 | P36: 318.02 | Q36: 6185.82 | R36: 587.5 | S36: 10094.3 | T36: 5195.28 | U36: 2643.98 | V36: =VLOOKUP(A36,[2]韩国KOSPI指数历史数据!$A:$B,2,) -> 1775.54 | W36: =VLOOKUP(A36,[3]日经225指数历史数据!$A:$B,2,) -> 9179.38 | X36: 1162.43 | Y36: =VLOOKUP(A36,[4]上证指数历史数据!$A:$B,2,) -> 2642.31 | Z36: =VLOOKUP(A36,[5]深证成份指数历史数据!$A:$B,2,) -> 11090.46 | AA36: =VLOOKUP(A36,[6]台湾加权指数历史数据!$A:$B,2,) -> 7927.31 | AB36: 20981.82 | AC36: 2936.48 | AD36: 5530.65 | AE36: =VLOOKUP(A36,[7]越南VN30指数历史数据!$A:$B,2,) -> 472.26 | AF36: 23921.25 | AG36: 9474.12 | AH36: 11499.64 | AI36: 1048.79 | AJ36: 1174.57
A37: 40412 | B37: 2349.07 | C37: 65585 | D37: 4370.1 | E37: 10150.65 | F37: 11879.72 | G37: 616.76 | H37: 1064.59 | I37: 2153.63 | J37: 31755.35 | K37: 21020.82 | L37: 2430.39 | M37: 5951.17 | N37: =VLOOKUP(A37,'[1]俄罗斯交易系统市值加权指数历史数据 (1)'!$A:$B,2,) -> 1421.47 | O37: 3507.44 | P37: 317.04 | Q37: 6183.14 | R37: 593.46 | S37: 10148.2 | T37: 5201.56 | U37: 2630.35 | V37: =VLOOKUP(A37,[2]韩国KOSPI指数历史数据!$A:$B,2,) -> 1729.56 | W37: =VLOOKUP(A37,[3]日经225指数历史数据!$A:$B,2,) -> 8991.06 | X37: 1139.8 | Y37: =VLOOKUP(A37,[4]上证指数历史数据!$A:$B,2,) -> 2610.74 | Z37: =VLOOKUP(A37,[5]深证成份指数历史数据!$A:$B,2,) -> 11034.73 | AA37: =VLOOKUP(A37,[6]台湾加权指数历史数据!$A:$B,2,) -> 7722.91 | AB37: 20597.35 | AC37: 2938.74 | AD37: 5408.7 | AE37: =VLOOKUP(A37,[7]越南VN30指数历史数据!$A:$B,2,) -> 450.41 | AF37: 23644.46 | AG37: 9604.31 | AH37: 11764.99 | AI37: 1021.72 | AJ37: 1174.57
A38: 40419 | B38: 2423.22 | C38: 66679 | D38: 4541.2 | E38: 10447.93 | F38: 12144.92 | G38: 643.36 | H38: 1104.51 | I38: 2233.75 | J38: 32592.87 | K38: 21673.71 | L38: 2476.19 | M38: 6134.62 | N38: =VLOOKUP(A38,'[1]俄罗斯交易系统市值加权指数历史数据 (1)'!$A:$B,2,) -> 1467.62 | O38: 3672.2 | P38: 329.35 | Q38: 6400.71 | R38: 609.99 | S38: 10599.4 | T38: 5428.15 | U38: 2746.23 | V38: =VLOOKUP(A38,[2]韩国KOSPI指数历史数据!$A:$B,2,) -> 1780.02 | W38: =VLOOKUP(A38,[3]日经225指数历史数据!$A:$B,2,) -> 9114.13 | X38: 1157.45 | Y38: =VLOOKUP(A38,[4]上证指数历史数据!$A:$B,2,) -> 2655.39 | Z38: =VLOOKUP(A38,[5]深证成份指数历史数据!$A:$B,2,) -> 11467.09 | AA38: =VLOOKUP(A38,[6]台湾加权指数历史数据!$A:$B,2,) -> 7830.21 | AB38: 20971.5 | AC38: 3002.56 | AD38: 5479.4 | AE38: =VLOOKUP(A38,[7]越南VN30指数历史数据!$A:$B,2,) -> 481.65 | AF38: 24825.46 | AG38: 9685.03 | AH38: 11701.11 | AI38: 1019.79 | AJ38: 1174.48
A39: 40426 | B39: 2436.77 | C39: 66807 | D39: 4560.3 | E39: 10462.77 | F39: 12097.09 | G39: 636.46 | H39: 1109.55 | I39: 2242.48 | J39: 32626.87 | K39: 22106.52 | L39: 2524.48 | M39: 6214.77 | N39: =VLOOKUP(A39,'[1]俄罗斯交易系统市值加权指数历史数据 (1)'!$A:$B,2,) -> 1487.09 | O39: 3725.82 | P39: 334.96 | Q39: 6467.69 | R39: 606.08 | S39: 10689.6 | T39: 5501.64 | U39: 2780.4 | V39: =VLOOKUP(A39,[2]韩国KOSPI指数历史数据!$A:$B,2,) -> 1802.58 | W39: =VLOOKUP(A39,[3]日经225指数历史数据!$A:$B,2,) -> 9239.17 | X39: 1171.06 | Y39: =VLOOKUP(A39,[4]上证指数历史数据!$A:$B,2,) -> 2663.21 | Z39: =VLOOKUP(A39,[5]深证成份指数历史数据!$A:$B,2,) -> 11530.99 | AA39: =VLOOKUP(A39,[6]台湾加权指数历史数据!$A:$B,2,) -> 7890.11 | AB39: 21257.39 | AC39: 3022.28 | AD39: 5640.05 | AE39: =VLOOKUP(A39,[7]越南VN30指数历史数据!$A:$B,2,) -> 470.51 | AF39: 24966.81 | AG39: 9648.39 | AH39: 11694.4 | AI39: 1002.27 | AJ39: 1176.86
A40: 40433 | B40: 2473.43 | C40: 67089 | D40: 4638.9 | E40: 10607.85 | F40: 12164.56 | G40: 651.44 | H40: 1125.59 | I40: 2315.61 | J40: 33046.69 | K40: 22499.78 | L40: 2539.42 | M40: 6209.76 | N40: =VLOOKUP(A40,'[1]俄罗斯交易系统市值加权指数历史数据 (1)'!$A:$B,2,) -> 1464.18 | O40: 3722.02 | P40: 334.54 | Q40: 6389.02 | R40: 638.62 | S40: 10588.6 | T40: 5508.45 | U40: 2757.37 | V40: =VLOOKUP(A40,[2]韩国KOSPI指数历史数据!$A:$B,2,) -> 1827.35 | W40: =VLOOKUP(A40,[3]日经225指数历史数据!$A:$B,2,) -> 9626.09 | X40: 1174.95 | Y40: =VLOOKUP(A40,[4]上证指数历史数据!$A:$B,2,) -> 2598.69 | Z40: =VLOOKUP(A40,[5]深证成份指数历史数据!$A:$B,2,) -> 11208.25 | AA40: =VLOOKUP(A40,[6]台湾加权指数历史数据!$A:$B,2,) -> 8158.33 | AB40: 21970.86 | AC40: 3076.37 | AD40: 5884.95 | AE40: =VLOOKUP(A40,[7]越南VN30指数历史数据!$A:$B,2,) -> 476.11 | AF40: 25258.33 | AG40: 9669.56 | AH40: 11683.77 | AI40: 979.36 | AJ40: 1176.86
...
